<?xml version='1.0' encoding='utf-8'?>
<mujoco model="nemo4b">
<compiler angle="radian" meshdir="assets" autolimits="true" />

  <option timestep="0.0035" iterations="8" ls_iterations="4">
    <flag eulerdamp="disable" />
  </option>

  <custom>
        <numeric data="2500" name="constraint_limit_stiffness" />
        <numeric data="27000" name="constraint_stiffness" />
        <numeric data="30" name="constraint_ang_damping" />
        <numeric data="80" name="constraint_vel_damping" />
        <numeric data="-0.05" name="ang_damping" />
        <numeric data="0.5" name="joint_scale_pos" />
        <numeric data="0.1" name="joint_scale_ang" />
        <numeric data="0" name="spring_mass_scale" />
        <numeric data="1" name="spring_inertia_scale" />
        <numeric data="20" name="matrix_inv_iterations" />
        <numeric data="15" name="solver_maxls" />
  </custom>


  <visual>
    <global ellipsoidinertia="true" />
  </visual>
  <default>
    <geom contype="0" conaffinity="0" condim="1" solref="0.005 1" />
    <equality solref="0.005 1" />
    <default class="robot">
      <site rgba="1 0 0 1" size="0.01" group="5" />
      <default class="visual">
        <geom group="2" type="mesh" contype="0" conaffinity="0" density="0" material="metallic" />
      </default>
      <default class="collision">
        <geom conaffinity="1" contype="2" rgba="0.5 0.5 0.5 1" material="metallic" />
        <default class="foot_sphere">
            <geom contype="1" conaffinity="1" size=".01" type="sphere"/>
          </default>
      </default>
    </default>
  </default>


  <asset>
    <material name="metallic" rgba="0.7 0.7 0.7 1" />
    <material name="black" rgba="0.2 0.2 0.2 1" />
    <material name="transparent" rgba="0 0 0 0" />

    <mesh file="pelvis.stl" />
    <mesh name="l_hip_pitch" file="l_hip_pitch.stl" />
    <mesh name="l_hip_roll" file="l_hip_roll.stl" />
    <mesh name="l_hip_yaw" file="l_hip_yaw.stl" />
    <mesh name="l_knee" file="l_knee.stl" />
    <mesh name="l_foot_pitch" file="l_foot_pitch.stl" />
    <mesh name="l_foot_roll" file="l_foot_roll.stl" />
    
    <mesh name="l_shoulder_pitch" file="l_shoulder_pitch.stl" />
    <mesh name="l_shoulder_roll" file="l_shoulder_roll.stl" />
    <mesh name="l_elbow" file="l_elbow.stl" />

    <mesh name="r_hip_pitch" file="l_hip_pitch.stl" scale="1 -1 1" />
    <mesh name="r_hip_roll" file="l_hip_roll.stl" scale="1 -1 1" />
    <mesh name="r_hip_yaw" file="l_hip_yaw.stl" scale="1 -1 1" />
    <mesh name="r_knee" file="l_knee.stl" scale="1 -1 1" />
    <mesh name="r_foot_pitch" file="l_foot_pitch.stl" scale="1 -1 1" />
    <mesh name="r_foot_roll" file="l_foot_roll.stl" scale="1 -1 1" />

    <mesh name="r_shoulder_pitch" file="l_shoulder_pitch.stl" scale="1 -1 1" />
    <mesh name="r_shoulder_roll" file="l_shoulder_roll.stl" scale="1 -1 1" />
    <mesh name="r_elbow" file="l_elbow.stl" scale="1 -1 1" />

  </asset>
<worldbody>
  <light name="spotlight" mode="targetbodycom" target="pelvis" pos="0 -6 4" cutoff="30" />
  <body name="pelvis" pos="0.0 0.0 0.6088" childclass="robot">
    <inertial pos="0.00505250 -0.00005977 0.18608225" mass="5.29698285" fullinertia="0.11381520 0.08283557 0.05217409 -0.00002232 0.00625310 -0.00006998" />
    <freejoint name="floating_base" />
    <site name="imu"/>
    <geom type="mesh" class="visual" mesh="pelvis" />
    <body name="l_hip_pitch" pos="0.0 0.0965 -0.112">
      <inertial pos="-0.01821923 -0.0 -3.205e-05" mass="1.8670971" fullinertia="0.00265583 0.00363357 0.00358009 -2e-07 -1.09e-06 -0.0" />
      <joint armature="0.005" damping="2" actuatorfrcrange="-47.4 47.4" name="l_hip_pitch" axis="0 1 0" range="-1.3 1.3" />
      <geom type="mesh" class="visual" mesh="l_hip_pitch" />
      <body name="l_hip_roll" pos="-0.07875 0.0 0.0">
        <inertial pos="-0.01740501 1.764e-05 -0.05845559" mass="2.00459959" fullinertia="0.0064706 0.00633136 0.00303949 4.7e-07 -0.00070962 9e-07" />
        <joint armature="0.005" damping="1" actuatorfrcrange="-23.7 23.7" name="l_hip_roll" axis="1 0 0" range="-0.4 1.5" />
        <geom type="mesh" class="visual" mesh="l_hip_roll" />
        <body name="l_hip_yaw" pos="0.00715 0.0 -0.1263">
          <inertial pos="3.205e-05 -0.0 -0.06053076999999999" mass="1.8670971" fullinertia="0.00358009 0.00363357 0.00265583 -0.0 -1.09e-06 -2e-07" />
          <joint armature="0.005" damping="1" actuatorfrcrange="-23.7 23.7" name="l_hip_yaw" axis="0 0 1" range="-1.0 1.0" />
          <geom type="mesh" class="visual" mesh="l_hip_yaw" />
          <!-- <geom class="collision" name="l_hip_yaw_col" pos="0 0 -0.06575" size="0.05284 0.05714 0.06575" type="box"/>
          -->
          <body name="l_knee" pos="0.0 0.0 -0.07875">
            <inertial pos="0.0 5e-05 -0.10289321" mass="0.58007416" fullinertia="0.0070466 0.00513742 0.00225232 -0.0 0.0 -0.0" />
            <joint armature="0.005" damping="4" actuatorfrcrange="-47.4 47.4" name="l_knee" axis="0 1 0" range="-0.3 2" />
            <geom type="mesh" class="visual" mesh="l_knee" />
            <!--
            <geom class="collision" name="l_knee_col" pos="0 0 -0.103" size="0.03178 0.07465 0.01145" type="box"/>
            -->
            <body name="l_foot_pitch" pos="0.0 0.0 -0.206">
              <inertial pos="0.01821923 -0.0 -3.205e-05" mass="1.8670971" fullinertia="0.00265583 0.00363357 0.00358009 -2e-07 1.09e-06 -0.0" />
              <joint armature="0.005" damping="2" actuatorfrcrange="-47.4 47.4" name="l_foot_pitch" axis="0 1 0" range="-2.0 2.0" />
              <geom type="mesh" class="visual" mesh="l_foot_pitch" />
              <body name="l_foot_roll" pos="0.07875 0.0 0.0">
                <inertial pos="0.00757956 1.139e-05 -0.03942379" mass="1.5526793" fullinertia="0.00385478 0.0054167 0.00391016 5.4e-07 0.0010808 3e-07" />
                <joint armature="0.005" damping="1" actuatorfrcrange="-23.7 23.7" name="l_foot_roll" axis="1 0 0" range="-1 1" />
                <geom type="mesh" class="visual" mesh="l_foot_roll" name="left_foot"/>
                <geom name="left_foot_1" class="foot_sphere" pos="0.0763 0.0455 -0.07775"/>
                <geom name="left_foot_2" class="foot_sphere" pos="0.0763 -0.0455 -0.07775"/>
                <geom name="left_foot_3" class="foot_sphere" pos="-0.1137 0.0455 -0.07775"/>
                <geom name="left_foot_4" class="foot_sphere" pos="-0.1137 -0.0455 -0.07775"/>
                <site name="left_foot" pos="0.0 0.0 -0.08275" />
              </body>
            </body>
          </body>
        </body>
      </body>
    </body>


    <body name="r_hip_pitch" pos="0.0 -0.0965 -0.112">
      <inertial pos="-0.01821923 -0.0 -3.205e-05" mass="1.8670971" fullinertia="0.00265583 0.00363357 0.00358009 -2e-07 -1.09e-06 -0.0" />
      <joint armature="0.005" damping="2" actuatorfrcrange="-47.4 47.4" name="r_hip_pitch" axis="0 1 0" range="-1.3 1.3" />
      <geom type="mesh" class="visual" mesh="r_hip_pitch" />
      <body name="r_hip_roll" pos="-0.07875 -0.0 0.0">
        <inertial pos="-0.01740501 1.764e-05 -0.05845559" mass="2.00459959" fullinertia="0.0064706 0.00633136 0.00303949 4.7e-07 -0.00070962 9e-07" />
        <joint armature="0.005" damping="1" actuatorfrcrange="-23.7 23.7" name="r_hip_roll" axis="1 0 0" range="-1.5 0.40" />
        <geom type="mesh" class="visual" mesh="r_hip_roll" />
        <body name="r_hip_yaw" pos="0.00715 -0.0 -0.1263">
          <inertial pos="3.205e-05 -0.0 -0.06053076999999999" mass="1.8670971" fullinertia="0.00358009 0.00363357 0.00265583 -0.0 -1.09e-06 -2e-07" />
          <joint armature="0.005" damping="1" actuatorfrcrange="-23.7 23.7" name="r_hip_yaw" axis="0 0 1" range="-1.0 1.0" />
          <geom type="mesh" class="visual" mesh="r_hip_yaw" />
          <!--
          <geom class="collision" name="r_hip_yaw_col" pos="0 0 -0.06575" size="0.05284 0.05714 0.06575" type="box"/>
          -->
          <body name="r_knee" pos="0.0 -0.0 -0.07875">
            <inertial pos="0.0 5e-05 -0.10289321" mass="0.58007416" fullinertia="0.0070466 0.00513742 0.00225232 -0.0 0.0 -0.0" />
            <joint armature="0.005" damping="4" actuatorfrcrange="-47.4 47.4" name="r_knee" axis="0 1 0" range="-0.3 2" />
            <geom type="mesh" class="visual" mesh="l_knee" />
            <!--
            <geom class="collision" name="r_knee_col" pos="0 0 -0.103" size="0.03178 0.07465 0.01145" type="box"/>
            -->
            <body name="r_foot_pitch" pos="0.0 -0.0 -0.206">
              <inertial pos="0.01821923 -0.0 -3.205e-05" mass="1.8670971" fullinertia="0.00265583 0.00363357 0.00358009 -2e-07 1.09e-06 -0.0" />
              <joint armature="0.005" damping="2" actuatorfrcrange="-47.4 47.4" name="r_foot_pitch" axis="0 1 0" range="-2.0 2.0" />
              <geom type="mesh" class="visual" mesh="l_foot_pitch" />
              <body name="r_foot_roll" pos="0.07875 -0.0 0.0">
                <inertial pos="0.00757956 1.139e-05 -0.03942379" mass="1.5526793" fullinertia="0.00385478 0.0054167 0.00391016 5.4e-07 0.0010808 3e-07" />
                <joint armature="0.005" damping="1" actuatorfrcrange="-23.7 23.7" name="r_foot_roll" axis="1 0 0" range="-1 1" />
                <geom type="mesh" class="visual" mesh="l_foot_roll" name="right_foot"/>
                <!--<geom class="collision" name="right_foot" pos="-0.0187 0 -0.07975" size="0.1 0.0505 0.006" type="box" />-->
                <geom name="right_foot_1" class="foot_sphere" pos="0.0763 0.0455 -0.07775"/>
                <geom name="right_foot_2" class="foot_sphere" pos="0.0763 -0.0455 -0.07775"/>
                <geom name="right_foot_3" class="foot_sphere" pos="-0.1137 0.0455 -0.07775"/>
                <geom name="right_foot_4" class="foot_sphere" pos="-0.1137 -0.0455 -0.07775"/>
                <site name="right_foot" pos="0.0 0.0 -0.08275" />
              </body>
            </body>
          </body>
        </body>
      </body>
    </body>

    <body name="l_shoulder_pitch" pos="-0.001404 0.1199 0.163">
      <inertial pos="0.0022 -0.05981 0.000" mass="0.89824188" diaginertia="0.00181720 0.00091278 0.00118927"/>
      <joint armature="0.005" damping="1" actuatorfrcrange="-23.7 23.7" name="l_shoulder_pitch" axis="0 1 0" range="-1.5 1.5" />
      <geom type="mesh" class="visual" mesh="l_shoulder_pitch" />
      <body name="l_shoulder_roll" pos="0.020174 0.0765 0.0009">
        <inertial pos="-0.01717369 0.00501388 -0.13591536" mass="1.01634729" diaginertia="0.00374627 0.00437525 0.00097343"/>
        <joint armature="0.005" damping="1" actuatorfrcrange="-23.7 23.7" name="l_shoulder_roll" axis="1 0 0" range="0.04 2.0" />
        <geom type="mesh" class="visual" mesh="l_shoulder_roll" />
        <body name="l_elbow" pos="-0.027502 0.0104  -0.173047">
          <inertial pos="0 -0.0113 -0.05618" mass="0.19590289" diaginertia="0.00111956 0.00122819 0.00011420"/>
          <joint armature="0.005" damping="1" actuatorfrcrange="-23.7 23.7" name="l_elbow" axis="0 1 0" range="-1.0 1.0" />
          <geom type="mesh" class="visual" mesh="l_elbow" />
        </body>
      </body>
    </body>

    <!-- Right arm (mirrored across xz-plane: y -> -y) -->
    <body name="r_shoulder_pitch" pos="-0.001404 -0.1199 0.163">
      <inertial pos="0.0022 0.05981 0.000" mass="0.89824188" diaginertia="0.00181720 0.00091278 0.00118927"/>
      <joint armature="0.005" damping="1" actuatorfrcrange="-23.7 23.7" name="r_shoulder_pitch" axis="0 1 0" range="-1.5 1.5" />
      <geom type="mesh" class="visual" mesh="r_shoulder_pitch" />
      <body name="r_shoulder_roll" pos="0.020174 -0.0765 0.0009">
        <inertial pos="-0.01717369 -0.00501388 -0.13591536" mass="1.01634729" diaginertia="0.00374627 0.00437525 0.00097343"/>
        <joint armature="0.005" damping="1" actuatorfrcrange="-23.7 23.7" name="r_shoulder_roll" axis="1 0 0" range="-2.0 -0.04" />
        <geom type="mesh" class="visual" mesh="r_shoulder_roll" />
        <body name="r_elbow" pos="-0.027502 -0.0104  -0.173047">
          <inertial pos="0 0.0113 -0.05618" mass="0.19590289" diaginertia="0.00111956 0.00122819 0.00011420"/>
          <joint armature="0.005" damping="1" actuatorfrcrange="-23.7 23.7" name="r_elbow" axis="0 1 0" range="-1.0 1.0" />
          <geom type="mesh" class="visual" mesh="r_elbow" />
        </body>
      </body>
    </body>
    <!-- End right arm -->

    <light name="tracking" mode="trackcom" pos="0 0 2" />
  </body>
</worldbody>
<actuator>
  <position kp="35.0" class="robot" name="l_hip_pitch" joint="l_hip_pitch" inheritrange="1"/>
  <position kp="25.0" class="robot" name="l_hip_roll" joint="l_hip_roll" inheritrange="1"/>
  <position kp="25.0" class="robot" name="l_hip_yaw" joint="l_hip_yaw" inheritrange="1"/>
  <position kp="35.0" class="robot" name="l_knee" joint="l_knee" inheritrange="1"/>
  <motor class="robot" name="l_foot_pitch" joint="l_foot_pitch"/>
  <motor class="robot" name="l_foot_roll" joint="l_foot_roll"/>

  <position kp="35.0" class="robot" name="r_hip_pitch" joint="r_hip_pitch" inheritrange="1"/>
  <position kp="25.0" class="robot" name="r_hip_roll" joint="r_hip_roll" inheritrange="1"/>
  <position kp="25.0" class="robot" name="r_hip_yaw" joint="r_hip_yaw" inheritrange="1"/>
  <position kp="35.0" class="robot" name="r_knee" joint="r_knee" inheritrange="1"/>
  <motor class="robot" name="r_foot_pitch" joint="r_foot_pitch"/>
  <motor class="robot" name="r_foot_roll" joint="r_foot_roll"/>

  <position kp="5.0" class="robot" name="l_shoulder_pitch" joint="l_shoulder_pitch" inheritrange="1"/>
  <position kp="5.0" class="robot" name="l_shoulder_roll" joint="l_shoulder_roll" inheritrange="1"/>
  <position kp="5.0" class="robot" name="l_elbow" joint="l_elbow" inheritrange="1"/>  

  <position kp="5.0" class="robot" name="r_shoulder_pitch" joint="r_shoulder_pitch" inheritrange="1"/>
  <position kp="5.0" class="robot" name="r_shoulder_roll" joint="r_shoulder_roll" inheritrange="1"/>
  <position kp="5.0" class="robot" name="r_elbow" joint="r_elbow" inheritrange="1"/>
</actuator>

<keyframe>
    <key name="home" qpos="0 0 0.63   1 0 0 0
    -0.698132 0 0 1.22173 -0.523599 0
    -0.698132 0 0 1.22173 -0.523599 0
    0 0.05 0
    0 -0.05 0" />
    <key name="sit"  qpos="-0.03 0 0.52   1 0 -0.045 0
    -0.9673 0 0 2.13 -1.0735 0
    -0.9673 0 0 2.13 -1.0735 0
    0 0.05 0
    0 -0.05 0"/>
    <key name="stand" qpos="0 0 0.63   1 0 0 0
    -1.06169705 0 0 1.22173 -0.08 0
    -1.06169705 0 0 1.22173 -0.08 0
    0 0.05 0
    0 -0.05 0" />
</keyframe>

<sensor>
    <gyro site="imu" name="gyro"/>
    <velocimeter site="imu" name="local_linvel"/>
    <accelerometer site="imu" name="accelerometer"/>
    <framezaxis objtype="site" objname="imu" name="upvector"/>
    <framexaxis objtype="site" objname="imu" name="forwardvector"/>
    <framelinvel objtype="site" objname="imu" name="global_linvel"/>
    <frameangvel objtype="site" objname="imu" name="global_angvel"/>
    <framepos objtype="site" objname="imu" name="position"/>
    <framequat objtype="site" objname="imu" name="orientation"/>
    <framelinvel objtype="site" objname="left_foot" name="left_foot_global_linvel"/>
    <framelinvel objtype="site" objname="right_foot" name="right_foot_global_linvel"/>
    <framepos objtype="site" objname="left_foot" name="left_foot_pos"/>
    <framepos objtype="site" objname="right_foot" name="right_foot_pos"/>
</sensor>

</mujoco>